Workbook

Sheet Summary
A1: VM0047 Area-based ARR Equation Summary
A4: Equation | B4: Tab Name | C4: Description | D4: Dependencies | E4: Status
A5: Eq4 | B5: Eq4_CWP_woody | C5: Total woody biomass carbon per hectare | D5: None | E5: Base calculation
A6: Eq6 | B6: Eq6_CWP_herb | C6: Non-woody biomass carbon per hectare | D6: None | E6: Base calculation
A7: Eq8 | B7: Eq8_CWP_DW | C7: Dead wood carbon per hectare | D7: None | E7: Base calculation
A8: Eq10 | B8: Eq10_CWP_LI | C8: Litter carbon per hectare | D8: None | E8: Base calculation
A9: Eq11 | B9: Eq11_Delta_SOC | C9: Soil organic carbon change | D9: None | E9: Base calculation
A10: Eq3 | B10: Eq3_Delta_woody | C10: Woody biomass carbon change | D10: Eq4 | E10: Links to Eq4
A11: Eq5 | B11: Eq5_Delta_herb | C11: Non-woody biomass carbon change | D11: Eq6 | E11: Links to Eq6
A12: Eq7 | B12: Eq7_Delta_DW | C12: Dead wood carbon change | D12: Eq8 | E12: Links to Eq8
A13: Eq9 | B13: Eq9_Delta_LI | C13: Litter carbon change | D13: Eq10 | E13: Links to Eq10
A14: Eq2 | B14: Eq2_Delta_biomass | C14: Total biomass carbon change | D14: Eq3,5,7,9 | E14: Aggregates all pools
A15: Eq1 | B15: Eq1_Project_total | C15: Project carbon change (CO2e) | D15: Eq2,11 | E15: Main project calculation
... A17: Eq34 | B17: Eq34_Annualized | C17: Annualized removals | D17: Eq30 | E17: Per year basis
A21: Notes:
A22: Blue cells: inputs & variables. Edit
A23: Orange cells: calculations or inputs from other tabs. Do not edit
A24: Green cells: equation output from calculation
A29: Additional Notes
A30: * Leakage (GHGLK,t): Set to 0. For area-based projects, VMD0054 module must be applied if there's displacement of agricultural activities (e.g., if riparian planting displaces farming). Your project protects agricultural fields (10:1 ratio), so leakage might be minimal, but it needs justification and calculation if applicable. * Uncertainty and Buffer Pool: No deduction for uncertainty (required if >5% per Section 9) or contribution to VCS buffer pool (via VMD0055 risk tool for non-permanence). * Monitoring and Data Sources: Assumes values (e.g., biomass growth from literature). VM0047 mandates ex-ante estimates but ex-post monitoring via remote sensing (for SI) and permanent plots (for pools). No sheet for monitoring plan or error propagation. * Additionality: Relies on PB >0, but no full demonstration (e.g., project method for barriers if needed). * Reversals and Reversibility: No accounting for potential losses (e.g., flooding in riparian zones). * Bamboo-Specific Guidelines: VM0047 doesn't have bamboo-specific rules, but your assumptions (e.g., culms/clump growth, allelopathy reducing understory) are reasonable from literature. However, bamboo's rhizomatous growth requires clumped sampling in plots. * V1.1 Updates: The Excel seems based on v1.0 (e.g., no mention of forested land eligibility or offsite biomass removal). Update to v1.1 clarifications (e.g., remote sensing for pre-existing biomass).

Sheet Total_Summary
A1: VM0047 Project Summary - 1000 ha Bambusa balcooa
A3: Key Project Metrics
A4: Project Area: | B4: =Assumptions!B8 -> 4000 | C4: hectare
A5: Species: | B5: Bambusa balcooa
A6: Project Duration: | B6: =Biomass!A25 -> 20 | C6: years
A7: Planting Density: | B7: =Assumptions!B17 -> 500 | C7: plants/ha
A8: Carbon Fraction (CF): | B8: =Biomass!A28 -> 0.47
A9: Root:Shoot Ratio (R): | B9: =Biomass!A30 -> 0.24
A10: SOC Accumulation: | B10: 0.5 t C/ha/year | C10: tC/ha/year
A13: Key Results by Year
A14: Year | B14: Gross CO2e (t) | C14: Net CO2e (t) | D14: Annual Rate (t/ha/year)
A15: 5 | B15: =Eq1_Project_total!I9 -> 1032654.3 | C15: =Eq30_Carbon_removals!I11 -> 213866.99 | D15: =Eq34_Annualized!I8/1000 -> 213.86699
A16: 10 | B16: =Eq1_Project_total!N9 -> 3084044.3 | C16: =Eq30_Carbon_removals!N11 -> 184863.68 | D16: =Eq34_Annualized!N8/1000 -> 184.86368
A17: 15 | B17: =Eq1_Project_total!S9 -> 4881792.7 | C17: =Eq30_Carbon_removals!S11 -> 189767.32 | D17: =Eq34_Annualized!S8/1000 -> 189.76732
A18: 20 | B18: =Eq1_Project_total!X9 -> 5869095.5 | C18: =Eq30_Carbon_removals!X11 -> 78540.929 | D18: =Eq34_Annualized!X8/1000 -> 78.540929
A21: 20-Year Project Totals
A22: Total Net CO2e Removed: | B22: =SUM(Eq30_Carbon_removals!E11:X11) -> 3211569
A23: Average Annual Rate: | B23: =B22/20 -> 160578.45

Sheet Assumptions
A1: Assumptions
A4: Variable | B4: Value | C4: Parameter | D4: Notes | E4: Year 1 | F4: Year 2 | G4: Year 3 | H4: Year 4 | I4: Year 5 | J4: Year 6 | K4: Year 7 | L4: Year 8 | M4: Year 9 | N4: Year 10 | O4: Year 11 | P4: Year 12 | Q4: Year 13 | R4: Year 14 | S4: Year 15 | T4: Year 16 | U4: Year 17 | V4: Year 18 | W4: Year 19 | X4: Year 20
B5: 20 | C5: Width of riparian planting zone, meters
B6: =((1000*B5)/10000) -> 2 | C6: Hectare equivalent of 1 km planting zone
B7: =SUM(E7:X7) -> 1000 | C7: Length of river banks newly planted, kms (both sides) | E7: 500 | F7: 500
B8: =X8 -> 4000 | C8: Plantation Size (ha) | E8: =E9 -> 2000 | F8: =IF(F9>0,E8+E9,E8) -> 4000 | G8: =IF(G9>0,F8+F9,F8) -> 4000 | H8: =IF(H9>0,G8+G9,G8) -> 4000 | I8: =IF(I9>0,H8+H9,H8) -> 4000 | J8: =IF(J9>0,I8+I9,I8) -> 4000 | K8: =IF(K9>0,J8+J9,J8) -> 4000 | L8: =IF(L9>0,K8+K9,K8) -> 4000 | M8: =IF(M9>0,L8+L9,L8) -> 4000 | ... X8: =IF(X9>0,W8+W9,W8) -> 4000
C9: New hectares planted | E9: =E7*$B6*2 -> 2000 | F9: =F7*$B6*2 -> 2000 | G9: =G7*$B6*2 -> 0 | H9: =H7*$B6*2 -> 0 | I9: =I7*$B6*2 -> 0 | J9: =J7*$B6*2 -> 0 | K9: =K7*$B6*2 -> 0 | L9: =L7*$B6*2 -> 0 | ... X9: =X7*$B6*2 -> 0
B10: 20 | C10: Carbon Credits per ha per year (tCO2e) | D10: =Total_Summary!B23/Assumptions!B8 -> 40.144613
B11: 10 | C11: Carbon Price (USD/tCO2e)
B12: 0.05 | C12: % annual carbon price increment
B13: 20 | C13: Project Duration (years)
B14: 0.08 | C14: Discount Rate
B15: 2 | C15: Start Year of Carbon Revenue
B17: 500 | C17: Planting Density, seedlings per ha | D17: EcoPlanet Bamboo uses 400 per ha
B18: =B17/(10/B5) -> 1000 | C18: Seedlings per km of riparian zone (single river bank)
B19: =B18*B7 -> 1000000 | C19: Total Seedlings Needed
B21: 0.5 | C21: SOC Accumulation: | D21: tC/ha/year, soil organic content
B23: 10 | C23: Ratio ha agricultural fields protected : ha bamboo | D23: Estimate. TBC by GIS modelling
B25: 0.46 | C25: Moisture content (freshly cut mature culm)
B27: 5 | C27: Mature canopy cover diameter

Sheet Seedling Density
A1: Seedling Density Calculator
A2: Density currently used in model | E2: 5
A3: Density (linear m) | B3: Rows # | C3: Riparian planting width | D3: Mature canopy width | E3: Mature coverage area (m²) | F3: Length for 1 ha coverage (m) | G3: Seedlings / ha | H3: Area per seedling (m²) | K3: Notes | M3: =Total_Summary!B22/Assumptions!B8 -> 802.89226
A4: 5 | B4: 1 | C4: =+A4*(B4-1) -> 0 | D4: =+C4+Assumptions!$B$27 -> 5 | E4: =+D4*A4 -> 25 | F4: =10000/D4 -> 2000 | G4: =+F4/A4*B4 -> 400 | H4: =+A4*A4 -> 25 | K4: A balanced, practical option is 5 m row spacing × 5 m in-row spacing (square grid):
A5: 5 | B5: 2 | C5: =+A5*(B5-1) -> 5 | D5: =+C5+Assumptions!$B$27 -> 10 | E5: =+D5*A5 -> 50 | F5: =10000/D5 -> 1000 | G5: =+F5/A5*B5 -> 400 | H5: =+A5*A5 -> 25 | K5: Rows across width: 5 rows (at 0 m, 5 m, 10 m, 15 m, 20 m from the water's edge).
A6: 5 | B6: 3 | C6: =+A6*(B6-1) -> 10 | D6: =+C6+Assumptions!$B$27 -> 15 | E6: =+D6*A6 -> 75 | F6: =10000/D6 -> 666.66667 | G6: =+F6/A6*B6 -> 400 | H6: =+A6*A6 -> 25 | K6: Trees per row: Depends on the riverbank length; e.g., for a 500 m length (equivalent to 1 ha of strip: 20 m × 500 m = 10,000 m²), you'd plant 100 trees/row × 5 rows = 500 trees (but adjust to exactly 400/ha by fine-tuning length-based spacing if needed).
A7: 5 | B7: 4 | C7: =+A7*(B7-1) -> 15 | D7: =+C7+Assumptions!$B$27 -> 20 | E7: =+D7*A7 -> 100 | F7: =10000/D7 -> 500 | G7: =+F7/A7*B7 -> 400 | H7: =+A7*A7 -> 25 | K7: Stagger rows (triangular grid) if using the 5×5 layout to increase density slightly without changing area per tree—offset alternate rows by 2.5 m.
A8: 5 | B8: 5 | C8: =+A8*(B8-1) -> 20 | D8: =+C8+Assumptions!$B$27 -> 25 | E8: =+D8*A8 -> 125 | F8: =10000/D8 -> 400 | G8: =+F8/A8*B8 -> 400 | H8: =+A8*A8 -> 25
A10: 4 | B10: 1 | C10: =+A10*(B10-1) -> 0 | D10: =+C10+Assumptions!$B$27 -> 5 | E10: =+D10*A10 -> 20 | F10: =10000/D10 -> 2000 | G10: =+F10/A10*B10 -> 500 | H10: =+A10*A10 -> 16
A11: =+A10 -> 4 | B11: 2 | C11: =+A11*(B11-1) -> 4 | D11: =+C11+Assumptions!$B$27 -> 9 | E11: =+D11*A11 -> 36 | F11: =10000/D11 -> 1111.1111 | G11: =+F11/A11*B11 -> 555.55556 | H11: =+A11*A11 -> 16
A12: =+A11 -> 4 | B12: 3 | C12: =+A12*(B12-1) -> 8 | D12: =+C12+Assumptions!$B$27 -> 13 | E12: =+D12*A12 -> 52 | F12: =10000/D12 -> 769.23077 | G12: =+F12/A12*B12 -> 576.92308 | H12: =+A12*A12 -> 16
A13: =+A12 -> 4 | B13: 4 | C13: =+A13*(B13-1) -> 12 | D13: =+C13+Assumptions!$B$27 -> 17 | E13: =+D13*A13 -> 68 | F13: =10000/D13 -> 588.23529 | G13: =+F13/A13*B13 -> 588.23529 | H13: =+A13*A13 -> 16
A14: =+A13 -> 4 | B14: 5 | C14: =+A14*(B14-1) -> 16 | D14: =+C14+Assumptions!$B$27 -> 21 | E14: =+D14*A14 -> 84 | F14: =10000/D14 -> 476.19048 | G14: =+F14/A14*B14 -> 595.2381 | H14: =+A14*A14 -> 16
A16: 4.3 | B16: 1 | C16: =+A16*(B16-1) -> 0 | D16: =+C16+Assumptions!$B$27 -> 5 | E16: =+D16*A16 -> 21.5 | F16: =10000/D16 -> 2000 | G16: =+F16/A16*B16 -> 465.11628 | H16: =+A16*A16 -> 18.49
A17: =+A16 -> 4.3 | B17: 2 | C17: =+A17*(B17-1) -> 4.3 | D17: =+C17+Assumptions!$B$27 -> 9.3 | E17: =+D17*A17 -> 39.99 | F17: =10000/D17 -> 1075.2688 | G17: =+F17/A17*B17 -> 500.12503 | H17: =+A17*A17 -> 18.49
A18: =+A17 -> 4.3 | B18: 3 | C18: =+A18*(B18-1) -> 8.6 | D18: =+C18+Assumptions!$B$27 -> 13.6 | E18: =+D18*A18 -> 58.48 | F18: =10000/D18 -> 735.29412 | G18: =+F18/A18*B18 -> 512.9959 | H18: =+A18*A18 -> 18.49
A19: =+A18 -> 4.3 | B19: 4 | C19: =+A19*(B19-1) -> 12.9 | D19: =+C19+Assumptions!$B$27 -> 17.9 | E19: =+D19*A19 -> 76.97 | F19: =10000/D19 -> 558.65922 | G19: =+F19/A19*B19 -> 519.68299 | H19: =+A19*A19 -> 18.49
A20: =+A19 -> 4.3 | B20: 5 | C20: =+A20*(B20-1) -> 17.2 | D20: =+C20+Assumptions!$B$27 -> 22.2 | E20: =+D20*A20 -> 95.46 | F20: =10000/D20 -> 450.45045 | G20: =+F20/A20*B20 -> 523.77959 | H20: =+A20*A20 -> 18.49
A22: 3.7915288 | B22: 1 | C22: =+A22*(B22-1) -> 0 | D22: =+C22+Assumptions!$B$27 -> 5 | E22: =+D22*A22 -> 18.957644 | F22: =10000/D22 -> 2000 | G22: =+F22/A22*B22 -> 527.49171 | H22: =+A22*A22 -> 14.37569
A23: =+A22 -> 3.7915288 | B23: 2 | C23: =+A23*(B23-1) -> 3.7915288 | D23: =+C23+Assumptions!$B$27 -> 8.7915288 | E23: =+D23*A23 -> 33.333334 | F23: =10000/D23 -> 1137.4586 | G23: =+F23/A23*B23 -> 599.99998 | H23: =+A23*A23 -> 14.37569
A24: =+A23 -> 3.7915288 | B24: 3 | C24: =+A24*(B24-1) -> 7.5830576 | D24: =+C24+Assumptions!$B$27 -> 12.583058 | E24: =+D24*A24 -> 47.709025 | F24: =10000/D24 -> 794.7194 | G24: =+F24/A24*B24 -> 628.81185 | H24: =+A24*A24 -> 14.37569
A25: =+A24 -> 3.7915288 | B25: 4 | C25: =+A25*(B25-1) -> 11.374586 | D25: =+C25+Assumptions!$B$27 -> 16.374586 | E25: =+D25*A25 -> 62.084715 | F25: =10000/D25 -> 610.70245 | G25: =+F25/A25*B25 -> 644.28096 | H25: =+A25*A25 -> 14.37569
A26: =+A25 -> 3.7915288 | B26: 5 | C26: =+A26*(B26-1) -> 15.166115 | D26: =+C26+Assumptions!$B$27 -> 20.166115 | E26: =+D26*A26 -> 76.460406 | F26: =10000/D26 -> 495.88133 | G26: =+F26/A26*B26 -> 653.93323 | H26: =+A26*A26 -> 14.37569
A28: 2.9120344 | B28: 1 | C28: =+A28*(B28-1) -> 0 | D28: =+C28+Assumptions!$B$27 -> 5 | E28: =+D28*A28 -> 14.560172 | F28: =10000/D28 -> 2000 | G28: =+F28/A28*B28 -> 686.80507 | H28: =+A28*A28 -> 8.4799444
A29: =+A28 -> 2.9120344 | B29: 2 | C29: =+A29*(B29-1) -> 2.9120344 | D29: =+C29+Assumptions!$B$27 -> 7.9120344 | E29: =+D29*A29 -> 23.040116 | F29: =10000/D29 -> 1263.8974 | G29: =+F29/A29*B29 -> 868.05117 | H29: =+A29*A29 -> 8.4799444
A30: =+A29 -> 2.9120344 | B30: 3 | C30: =+A30*(B30-1) -> 5.8240688 | D30: =+C30+Assumptions!$B$27 -> 10.824069 | E30: =+D30*A30 -> 31.520061 | F30: =10000/D30 -> 923.867 | G30: =+F30/A30*B30 -> 951.77481 | H30: =+A30*A30 -> 8.4799444
A31: =+A30 -> 2.9120344 | B31: 4 | C31: =+A31*(B31-1) -> 8.7361032 | D31: =+C31+Assumptions!$B$27 -> 13.736103 | E31: =+D31*A31 -> 40.000005 | F31: =10000/D31 -> 728.00851 | G31: =+F31/A31*B31 -> 999.99987 | H31: =+A31*A31 -> 8.4799444
A32: =+A31 -> 2.9120344 | B32: 5 | C32: =+A32*(B32-1) -> 11.648138 | D32: =+C32+Assumptions!$B$27 -> 16.648138 | E32: =+D32*A32 -> 48.47995 | F32: =10000/D32 -> 600.66779 | G32: =+F32/A32*B32 -> 1031.3542 | H32: =+A32*A32 -> 8.4799444

Sheet Biomass
A1: Biomass Calculations
R2: Do different unit calculation costs elsewhere as this has no costs or ER reductions - but acts as a guide for breakeven
B3: Most critical to ER | R3: year 1 value
A4: Single Bambusa Balcooa plant - Values in DRY WEIGHT (kilograms) | M4: Per seedling calculations | R4: =+Assumptions!B11 -> 10 | V4: AM Version 1 | Y4: Adriaan's Tana plant | AB4: Allahabad, India | AE4: Kerala Forest Research Institute | AH4: Roxb
A5: Year | B5: Average culms, per clump | C5: Avg Culm Weight (kg) | D5: Above-ground Biomass (kg) | E5: Above-ground Carbon Stock (tC/ha) | F5: Below-ground Biomass (kg) | G5: Below-ground Carbon Stock (tC/ha) | H5: Total Biomass (kg) | I5: Total Biomass (t/ha) | J5: Carbon Stock (tC/ha) | K5: tCO2e/ha | M5: Increase in biomass (Kg) | N5: Increase in Total Biomass (tonnes) / seedling | O5: Increase in carbon stock (tC/seedling) | P5: tCO2e/seedling | R5: Potential $ value per seedling | S5: Cumulative $ carbon value per seedling | V5: Average culms, per clump | W5: Avg Culm Weight (kg) | Y5: Average culms, per clump | Z5: Avg Culm dry Weight (kg) | AB5: Average culms, per clump | AC5: Avg Culm Weight (kg) | AE5: Average culms, per clump | AF5: Avg Culm Weight (kg) | AH5: Average culms, per clump | AI5: Avg Culm Weight (kg)
A6: 1 | B6: 1.5 | C6: 1.2 | D6: =C6*B6 -> 1.8 | E6: =(D6*Assumptions!B$17)/1000 -> 0.9 | F6: =D6*Biomass!A$30 -> 0.432 | G6: =(F6*Assumptions!B$17)/1000 -> 0.216 | H6: =D6+F6 -> 2.232 | I6: =(H6*Assumptions!B$17)/1000 -> 1.116 | J6: =I6*$A$28 -> 0.52452 | K6: =J6*A$29 -> 1.92324 | M6: =+H6 -> 2.232 | N6: =+M6/1000 -> 0.002232 | O6: =N6*$A$28 -> 0.00104904 | P6: =+O6*$A$29 -> 0.00384648 | R6: =+P6*R$4 -> 0.0384648 | S6: =+R6 -> 0.0384648 | V6: 1.5 | W6: 1.2 | Y6: 1 | Z6: 0
A7: 2 | B7: 3.5 | C7: 2.4 | D7: =C7*B7 -> 8.4 | E7: =(D7*Assumptions!B$17)/1000 -> 4.2 | F7: =D7*Biomass!A$30 -> 2.016 | G7: =(F7*Assumptions!B$17)/1000 -> 1.008 | H7: =D7+F7 -> 10.416 | I7: =(H7*Assumptions!B$17)/1000 -> 5.208 | J7: =I7*$A$28 -> 2.44776 | K7: =J7*A$29 -> 8.97512 | M7: =+H7-H6 -> 8.184 | N7: =+M7/1000 -> 0.008184 | O7: =N7*$A$28 -> 0.00384648 | P7: =+O7*$A$29 -> 0.01410376 | R7: =+P7*R$4 -> 0.1410376 | S7: =+R7+S6 -> 0.1795024 | V7: 3.5 | W7: 2.4 | Y7: =+Y$18/COUNTA(V6:V18)+Y6 -> 14.846154 | Z7: =+Z$18/12 -> 0.85833333
A8: 3 | B8: 5.5 | C8: 6 | D8: =C8*B8 -> 33 | E8: =(D8*Assumptions!B$17)/1000 -> 16.5 | F8: =D8*Biomass!A$30 -> 7.92 | G8: =(F8*Assumptions!B$17)/1000 -> 3.96 | H8: =D8+F8 -> 40.92 | I8: =(H8*Assumptions!B$17)/1000 -> 20.46 | J8: =I8*$A$28 -> 9.6162 | K8: =J8*A$29 -> 35.2594 | M8: =+H8-H7 -> 30.504 | N8: =+M8/1000 -> 0.030504 | O8: =N8*$A$28 -> 0.01433688 | P8: =+O8*$A$29 -> 0.05256856 | R8: =+P8*R$4 -> 0.5256856 | S8: =+R8+S7 -> 0.705188 | V8: 5.5 | W8: 6 | Y8: =+Y$18/COUNTA(V7:V19)+Y7 -> 28.692308 | Z8: =+Z$18/12+Z7 -> 1.7166667
A9: 4 | B9: 9 | C9: 7 | D9: =C9*B9 -> 63 | E9: =(D9*Assumptions!B$17)/1000 -> 31.5 | F9: =D9*Biomass!A$30 -> 15.12 | G9: =(F9*Assumptions!B$17)/1000 -> 7.56 | H9: =D9+F9 -> 78.12 | I9: =(H9*Assumptions!B$17)/1000 -> 39.06 | J9: =I9*$A$28 -> 18.3582 | K9: =J9*A$29 -> 67.3134 | M9: =+H9-H8 -> 37.2 | N9: =+M9/1000 -> 0.0372 | O9: =N9*$A$28 -> 0.017484 | P9: =+O9*$A$29 -> 0.064108 | R9: =+P9*R$4 -> 0.64108 | S9: =+R9+S8 -> 1.346268 | V9: 9 | W9: 7 | Y9: =+Y$18/COUNTA(V8:V20)+Y8 -> 42.538462 | Z9: =+Z$18/12+Z8 -> 2.575
A10: 5 | B10: 15 | C10: 7 | D10: =C10*B10 -> 105 | E10: =(D10*Assumptions!B$17)/1000 -> 52.5 | F10: =D10*Biomass!A$30 -> 25.2 | G10: =(F10*Assumptions!B$17)/1000 -> 12.6 | H10: =D10+F10 -> 130.2 | I10: =(H10*Assumptions!B$17)/1000 -> 65.1 | J10: =I10*$A$28 -> 30.597 | K10: =J10*A$29 -> 112.189 | M10: =+H10-H9 -> 52.08 | N10: =+M10/1000 -> 0.05208 | O10: =N10*$A$28 -> 0.0244776 | P10: =+O10*$A$29 -> 0.0897512 | R10: =+P10*R$4 -> 0.897512 | S10: =+R10+S9 -> 2.24378 | V10: 15 | W10: 7 | Y10: =+Y$18/COUNTA(V9:V21)+Y9 -> 56.384615 | Z10: =+Z$18/12+Z9 -> 3.4333333
A11: 6 | B11: 20 | C11: 7 | D11: =C11*B11 -> 140 | E11: =(D11*Assumptions!B$17)/1000 -> 70 | F11: =D11*Biomass!A$30 -> 33.6 | G11: =(F11*Assumptions!B$17)/1000 -> 16.8 | H11: =D11+F11 -> 173.6 | I11: =(H11*Assumptions!B$17)/1000 -> 86.8 | J11: =I11*$A$28 -> 40.796 | K11: =J11*A$29 -> 149.58533 | M11: =+H11-H10 -> 43.4 | N11: =+M11/1000 -> 0.0434 | O11: =N11*$A$28 -> 0.020398 | P11: =+O11*$A$29 -> 0.074792667 | R11: =+P11*R$4 -> 0.74792667 | S11: =+R11+S10 -> 2.9917067 | V11: 20 | W11: 7 | Y11: =+Y$18/COUNTA(V10:V22)+Y10 -> 70.230769 | Z11: =+Z$18/12+Z10 -> 4.2916667
A12: 7 | B12: 27 | C12: 7 | D12: =C12*B12 -> 189 | E12: =(D12*Assumptions!B$17)/1000 -> 94.5 | F12: =D12*Biomass!A$30 -> 45.36 | G12: =(F12*Assumptions!B$17)/1000 -> 22.68 | H12: =D12+F12 -> 234.36 | I12: =(H12*Assumptions!B$17)/1000 -> 117.18 | J12: =I12*$A$28 -> 55.0746 | K12: =J12*A$29 -> 201.9402 | M12: =+H12-H11 -> 60.76 | N12: =+M12/1000 -> 0.06076 | O12: =N12*$A$28 -> 0.0285572 | P12: =+O12*$A$29 -> 0.10470973 | R12: =+P12*R$4 -> 1.0470973 | S12: =+R12+S11 -> 4.038804 | V12: 27 | W12: 7 | Y12: =+Y$18/COUNTA(V11:V23)+Y11 -> 84.076923 | Z12: =+Z$18/12+Z11 -> 5.15 | AH12: 19.5
A13: 8 | B13: 35 | C13: 7 | D13: =C13*B13 -> 245 | E13: =(D13*Assumptions!B$17)/1000 -> 122.5 | F13: =D13*Biomass!A$30 -> 58.8 | G13: =(F13*Assumptions!B$17)/1000 -> 29.4 | H13: =D13+F13 -> 303.8 | I13: =(H13*Assumptions!B$17)/1000 -> 151.9 | J13: =I13*$A$28 -> 71.393 | K13: =J13*A$29 -> 261.77433 | M13: =+H13-H12 -> 69.44 | N13: =+M13/1000 -> 0.06944 | O13: =N13*$A$28 -> 0.0326368 | P13: =+O13*$A$29 -> 0.11966827 | R13: =+P13*R$4 -> 1.1966827 | S13: =+R13+S12 -> 5.2354867 | V13: 35 | W13: 7 | Y13: =+Y$18/COUNTA(V12:V24)+Y12 -> 97.923077 | Z13: =+Z$18/12+Z12 -> 6.0083333
A14: 9 | B14: 40 | C14: 7 | D14: =C14*B14 -> 280 | E14: =(D14*Assumptions!B$17)/1000 -> 140 | F14: =D14*Biomass!A$30 -> 67.2 | G14: =(F14*Assumptions!B$17)/1000 -> 33.6 | H14: =D14+F14 -> 347.2 | I14: =(H14*Assumptions!B$17)/1000 -> 173.6 | J14: =I14*$A$28 -> 81.592 | K14: =J14*A$29 -> 299.17067 | M14: =+H14-H13 -> 43.4 | N14: =+M14/1000 -> 0.0434 | O14: =N14*$A$28 -> 0.020398 | P14: =+O14*$A$29 -> 0.074792667 | R14: =+P14*R$4 -> 0.74792667 | S14: =+R14+S13 -> 5.9834133 | V14: 40 | W14: 7 | Y14: =+Y$18/COUNTA(V13:V25)+Y13 -> 111.76923 | Z14: =+Z$18/12+Z13 -> 6.8666667
A15: 10 | B15: 45 | C15: 7 | D15: =C15*B15 -> 315 | E15: =(D15*Assumptions!B$17)/1000 -> 157.5 | F15: =D15*Biomass!A$30 -> 75.6 | G15: =(F15*Assumptions!B$17)/1000 -> 37.8 | H15: =D15+F15 -> 390.6 | I15: =(H15*Assumptions!B$17)/1000 -> 195.3 | J15: =I15*$A$28 -> 91.791 | K15: =J15*A$29 -> 336.567 | M15: =+H15-H14 -> 43.4 | N15: =+M15/1000 -> 0.0434 | O15: =N15*$A$28 -> 0.020398 | P15: =+O15*$A$29 -> 0.074792667 | R15: =+P15*R$4 -> 0.74792667 | S15: =+R15+S14 -> 6.73134 | V15: 45 | W15: 7 | Y15: =+Y$18/COUNTA(V14:V26)+Y14 -> 126.76923 | Z15: =+Z$18/12+Z14 -> 7.725
A16: 11 | B16: 50 | C16: 7 | D16: =C16*B16 -> 350 | E16: =(D16*Assumptions!B$17)/1000 -> 175 | F16: =D16*Biomass!A$30 -> 84 | G16: =(F16*Assumptions!B$17)/1000 -> 42 | H16: =D16+F16 -> 434 | I16: =(H16*Assumptions!B$17)/1000 -> 217 | J16: =I16*$A$28 -> 101.99 | K16: =J16*A$29 -> 373.96333 | M16: =+H16-H15 -> 43.4 | N16: =+M16/1000 -> 0.0434 | O16: =N16*$A$28 -> 0.020398 | P16: =+O16*$A$29 -> 0.074792667 | R16: =+P16*R$4 -> 0.74792667 | S16: =+R16+S15 -> 7.4792667 | V16: 50 | W16: 7 | Y16: =+Y$18/COUNTA(V15:V27)+Y15 -> 143.13287 | Z16: =+Z$18/12+Z15 -> 8.5833333
A17: 12 | B17: 55 | C17: 7 | D17: =C17*B17 -> 385 | E17: =(D17*Assumptions!B$17)/1000 -> 192.5 | F17: =D17*Biomass!A$30 -> 92.4 | G17: =(F17*Assumptions!B$17)/1000 -> 46.2 | H17: =D17+F17 -> 477.4 | I17: =(H17*Assumptions!B$17)/1000 -> 238.7 | J17: =I17*$A$28 -> 112.189 | K17: =J17*A$29 -> 411.35967 | M17: =+H17-H16 -> 43.4 | N17: =+M17/1000 -> 0.0434 | O17: =N17*$A$28 -> 0.020398 | P17: =+O17*$A$29 -> 0.074792667 | R17: =+P17*R$4 -> 0.74792667 | S17: =+R17+S16 -> 8.2271933 | V17: 55 | W17: 7 | Y17: =+Y$18/COUNTA(V16:V28)+Y16 -> 161.13287 | Z17: =+Z$18/12+Z16 -> 9.4416667
A18: 13 | B18: 60 | C18: 7 | D18: =C18*B18 -> 420 | E18: =(D18*Assumptions!B$17)/1000 -> 210 | F18: =D18*Biomass!A$30 -> 100.8 | G18: =(F18*Assumptions!B$17)/1000 -> 50.4 | H18: =D18+F18 -> 520.8 | I18: =(H18*Assumptions!B$17)/1000 -> 260.4 | J18: =I18*$A$28 -> 122.388 | K18: =J18*A$29 -> 448.756 | M18: =+H18-H17 -> 43.4 | N18: =+M18/1000 -> 0.0434 | O18: =N18*$A$28 -> 0.020398 | P18: =+O18*$A$29 -> 0.074792667 | R18: =+P18*R$4 -> 0.74792667 | S18: =+R18+S17 -> 8.97512 | V18: 60 | W18: 7 | Y18: 180 | Z18: 10.3
A19: 14 | B19: 65 | C19: 7 | D19: =C19*B19 -> 455 | E19: =(D19*Assumptions!B$17)/1000 -> 227.5 | F19: =D19*Biomass!A$30 -> 109.2 | G19: =(F19*Assumptions!B$17)/1000 -> 54.6 | H19: =D19+F19 -> 564.2 | I19: =(H19*Assumptions!B$17)/1000 -> 282.1 | J19: =I19*$A$28 -> 132.587 | K19: =J19*A$29 -> 486.15233 | M19: =+H19-H18 -> 43.4 | N19: =+M19/1000 -> 0.0434 | O19: =N19*$A$28 -> 0.020398 | P19: =+O19*$A$29 -> 0.074792667 | R19: =+P19*R$4 -> 0.74792667 | S19: =+R19+S18 -> 9.7230467 | V19: 65 | W19: 7 | Y19: 180 | Z19: 10.3
A20: 15 | B20: 70 | C20: 7 | D20: =C20*B20 -> 490 | E20: =(D20*Assumptions!B$17)/1000 -> 245 | F20: =D20*Biomass!A$30 -> 117.6 | G20: =(F20*Assumptions!B$17)/1000 -> 58.8 | H20: =D20+F20 -> 607.6 | I20: =(H20*Assumptions!B$17)/1000 -> 303.8 | J20: =I20*$A$28 -> 142.786 | K20: =J20*A$29 -> 523.54867 | M20: =+H20-H19 -> 43.4 | N20: =+M20/1000 -> 0.0434 | O20: =N20*$A$28 -> 0.020398 | P20: =+O20*$A$29 -> 0.074792667 | R20: =+P20*R$4 -> 0.74792667 | S20: =+R20+S19 -> 10.470973 | V20: 70 | W20: 7 | Y20: 180 | Z20: 10.3
A21: 16 | B21: 75 | C21: 7 | D21: =C21*B21 -> 525 | E21: =(D21*Assumptions!B$17)/1000 -> 262.5 | F21: =D21*Biomass!A$30 -> 126 | G21: =(F21*Assumptions!B$17)/1000 -> 63 | H21: =D21+F21 -> 651 | I21: =(H21*Assumptions!B$17)/1000 -> 325.5 | J21: =I21*$A$28 -> 152.985 | K21: =J21*A$29 -> 560.945 | M21: =+H21-H20 -> 43.4 | N21: =+M21/1000 -> 0.0434 | O21: =N21*$A$28 -> 0.020398 | P21: =+O21*$A$29 -> 0.074792667 | R21: =+P21*R$4 -> 0.74792667 | S21: =+R21+S20 -> 11.2189 | V21: 75 | W21: 7 | Y21: 180 | Z21: 10.3
A22: 17 | B22: 78 | C22: 7 | D22: =C22*B22 -> 546 | E22: =(D22*Assumptions!B$17)/1000 -> 273 | F22: =D22*Biomass!A$30 -> 131.04 | G22: =(F22*Assumptions!B$17)/1000 -> 65.52 | H22: =D22+F22 -> 677.04 | I22: =(H22*Assumptions!B$17)/1000 -> 338.52 | J22: =I22*$A$28 -> 159.1044 | K22: =J22*A$29 -> 583.3828 | M22: =+H22-H21 -> 26.04 | N22: =+M22/1000 -> 0.02604 | O22: =N22*$A$28 -> 0.0122388 | P22: =+O22*$A$29 -> 0.0448756 | R22: =+P22*R$4 -> 0.448756 | S22: =+R22+S21 -> 11.667656 | V22: 78 | W22: 7 | Y22: 180 | Z22: 10.3
A23: 18 | B23: 80 | C23: 7 | D23: =C23*B23 -> 560 | E23: =(D23*Assumptions!B$17)/1000 -> 280 | F23: =D23*Biomass!A$30 -> 134.4 | G23: =(F23*Assumptions!B$17)/1000 -> 67.2 | H23: =D23+F23 -> 694.4 | I23: =(H23*Assumptions!B$17)/1000 -> 347.2 | J23: =I23*$A$28 -> 163.184 | K23: =J23*A$29 -> 598.34133 | M23: =+H23-H22 -> 17.36 | N23: =+M23/1000 -> 0.01736 | O23: =N23*$A$28 -> 0.0081592 | P23: =+O23*$A$29 -> 0.029917067 | R23: =+P23*R$4 -> 0.29917067 | S23: =+R23+S22 -> 11.966827 | V23: 80 | W23: 7 | Y23: 180 | Z23: 10.3
A24: 19 | B24: 82 | C24: 7 | D24: =C24*B24 -> 574 | E24: =(D24*Assumptions!B$17)/1000 -> 287 | F24: =D24*Biomass!A$30 -> 137.76 | G24: =(F24*Assumptions!B$17)/1000 -> 68.88 | H24: =D24+F24 -> 711.76 | I24: =(H24*Assumptions!B$17)/1000 -> 355.88 | J24: =I24*$A$28 -> 167.2636 | K24: =J24*A$29 -> 613.29987 | M24: =+H24-H23 -> 17.36 | N24: =+M24/1000 -> 0.01736 | O24: =N24*$A$28 -> 0.0081592 | P24: =+O24*$A$29 -> 0.029917067 | R24: =+P24*R$4 -> 0.29917067 | S24: =+R24+S23 -> 12.265997 | V24: 82 | W24: 7 | Y24: 180 | Z24: 10.3
A25: 20 | B25: 84 | C25: 7 | D25: =C25*B25 -> 588 | E25: =(D25*Assumptions!B$17)/1000 -> 294 | F25: =D25*Biomass!A$30 -> 141.12 | G25: =(F25*Assumptions!B$17)/1000 -> 70.56 | H25: =D25+F25 -> 729.12 | I25: =(H25*Assumptions!B$17)/1000 -> 364.56 | J25: =I25*$A$28 -> 171.3432 | K25: =J25*A$29 -> 628.2584 | M25: =+H25-H24 -> 17.36 | N25: =+M25/1000 -> 0.01736 | O25: =N25*$A$28 -> 0.0081592 | P25: =+O25*$A$29 -> 0.029917067 | R25: =+P25*R$4 -> 0.29917067 | S25: =+R25+S24 -> 12.565168 | V25: 84 | W25: 7 | Y25: 180 | Z25: 10.3
B26: Most critical to ER
A28: 0.47 | B28: Carbon Stock: Total biomass (AGB + BGB) × 0.47 (default carbon fraction for tropical woody plants per IPCC 2003, referenced in AR-ACM0003).
A29: 3.6666667 | B29: tCO2e Conversion: Under AR-ACM0003 (Afforestation and Reforestation of Lands Except Wetlands, v02.0), CO2e is calculated as carbon stock × (44/12) = carbon stock × 3.667. This represents the CO2 equivalent of the standing carbon stock (cumulative sequestration, assuming zero baseline emissions on degraded land, no non-CO2 GHGs, and no leakage). Values are in kg CO2e per single seedling (equivalent to 0.000[value] t CO2e).
A30: 0.24 | B30: Root:Shoot Ratio (IPCC default tropical) | D30: this gives the below ground biomass
A33: Notes:
A34: Individual Culm Weights: Assuming mature Bambusa balcooa culms average 6-8 kg dry weight (considering thick walls, 15-20m height). An average sample in Tana weighed 19 kgs (10.3 kg dry weight).
A35: Above-ground biomass includes culms, branches, and leaves, derived using non-destructive allometric models.
A36: A 12-year old clump in Tana had 180-200 culms by Year 12

Sheet CAPEX
A1: Capex
A4: Variable | B4: Value | C4: Description (with units) | D4: Unit Cost | E4: Year 1 | F4: Year 2 | G4: Year 3 | H4: Year 4 | I4: Year 5 | J4: Year 6 | K4: Year 7 | L4: Year 8 | M4: Year 9 | N4: Year 10 | O4: Year 11 | P4: Year 12 | Q4: Year 13 | R4: Year 14 | S4: Year 15 | T4: Year 16 | U4: Year 17 | V4: Year 18 | W4: Year 19 | X4: Year 20
B5: US$ | C5: Land Preparation | D5: 50 | E5: =$D5*Assumptions!E9 -> 100000 | F5: =$D5*Assumptions!F9 -> 100000 | G5: =$D5*Assumptions!G9 -> 0 | H5: =$D5*Assumptions!H9 -> 0 | I5: =$D5*Assumptions!I9 -> 0 | J5: =$D5*Assumptions!J9 -> 0 | K5: =$D5*Assumptions!K9 -> 0 | L5: =$D5*Assumptions!L9 -> 0 | ... X5: =$D5*Assumptions!X9 -> 0
B6: US$ | C6: Bamboo Seedlings, delivered to site | D6: 1.5 | E6: =$D6*(Assumptions!E9*Assumptions!$B17) -> 1500000 | F6: =$D6*(Assumptions!F9*Assumptions!$B17) -> 1500000 | G6: =$D6*(Assumptions!G9*Assumptions!$B17) -> 0 | H6: =$D6*(Assumptions!H9*Assumptions!$B17) -> 0 | I6: =$D6*(Assumptions!I9*Assumptions!$B17) -> 0 | J6: =$D6*(Assumptions!J9*Assumptions!$B17) -> 0 | K6: =$D6*(Assumptions!K9*Assumptions!$B17) -> 0 | L6: =$D6*(Assumptions!L9*Assumptions!$B17) -> 0 | ... X6: =$D6*(Assumptions!X9*Assumptions!$B17) -> 0
B7: US$ | C7: Planting Labour, per ha | D7: 25 | E7: =$D7*Assumptions!E9 -> 50000 | F7: =$D7*Assumptions!F9 -> 50000 | G7: =$D7*Assumptions!G9 -> 0 | H7: =$D7*Assumptions!H9 -> 0 | I7: =$D7*Assumptions!I9 -> 0 | J7: =$D7*Assumptions!J9 -> 0 | K7: =$D7*Assumptions!K9 -> 0 | L7: =$D7*Assumptions!L9 -> 0 | ... X7: =$D7*Assumptions!X9 -> 0
B8: US$ | C8: Irrigation Setup, per ha | D8: 0 | E8: =$D8*Assumptions!E9 -> 0 | F8: =$D8*Assumptions!F9 -> 0 | G8: =$D8*Assumptions!G9 -> 0 | H8: =$D8*Assumptions!H9 -> 0 | I8: =$D8*Assumptions!I9 -> 0 | J8: =$D8*Assumptions!J9 -> 0 | K8: =$D8*Assumptions!K9 -> 0 | L8: =$D8*Assumptions!L9 -> 0 | ... X8: =$D8*Assumptions!X9 -> 0
B9: US$ | C9: Infrastructure | D9: 100000 | E9: =D9 -> 100000
B10: US$ | C10: Vehicles & Equipment | D10: 150000 | E10: =D10 -> 150000
B11: US$ | C11: Tissue culture lab & accessories | D11: 50000 | E11: =D11 -> 50000
B12: US$ | C12: Other
B13: US$ | C13: Other
B14: US$ | C14: Other
B15: US$ | C15: Other
B16: US$ | C16: Other
B17: US$ | C17: Other
B18: US$ | C18: Other
B19: US$ | C19: TOTAL | E19: =SUM(E5:E18) -> 1950000 | F19: =SUM(F5:F18) -> 1650000 | G19: =SUM(G5:G18) -> 0 | H19: =SUM(H5:H18) -> 0 | I19: =SUM(I5:I18) -> 0 | J19: =SUM(J5:J18) -> 0 | K19: =SUM(K5:K18) -> 0 | L19: =SUM(L5:L18) -> 0 | ... X19: =SUM(X5:X18) -> 0
A24: Notes

Sheet HR
A1: Human Resources
A4: Variable | B4: Value | C4: Position Head Count | D4: Notes | E4: Year 1 | F4: Year 2 | G4: Year 3 | H4: Year 4 | I4: Year 5 | J4: Year 6 | K4: Year 7 | L4: Year 8 | M4: Year 9 | N4: Year 10 | O4: Year 11 | P4: Year 12 | Q4: Year 13 | R4: Year 14 | S4: Year 15 | T4: Year 16 | U4: Year 17 | V4: Year 18 | W4: Year 19 | X4: Year 20
B5: Unit | C5: Program Manager | E5: 1 | F5: 1 | G5: 1 | H5: 1 | I5: 1 | J5: 1 | K5: 1 | L5: 1 | M5: 1 | N5: 1 | O5: 1 | P5: 1 | Q5: 1 | R5: 1 | S5: 1 | T5: 1 | U5: 1 | V5: 1 | W5: 1 | X5: 1
B6: Unit | C6: Logistic Manager | E6: 1 | F6: 1 | G6: 1 | H6: 1 | I6: 1 | J6: 1 | K6: 1 | L6: 1 | M6: 1 | N6: 1 | O6: 1 | P6: 1 | Q6: 1 | R6: 1 | S6: 1 | T6: 1 | U6: 1 | V6: 1 | W6: 1 | X6: 1
B7: Unit | C7: Other staff | E7: 1 | F7: 1 | G7: 1 | H7: 1 | I7: 1 | J7: 1 | K7: 1 | L7: 1 | M7: 1 | N7: 1 | O7: 1 | P7: 1 | Q7: 1 | R7: 1 | S7: 1 | T7: 1 | U7: 1 | V7: 1 | W7: 1 | X7: 1
B8: Unit | C8: Other staff | E8: 1 | F8: 1 | G8: 1 | H8: 1 | I8: 1 | J8: 1 | K8: 1 | L8: 1 | M8: 1 | N8: 1 | O8: 1 | P8: 1 | Q8: 1 | R8: 1 | S8: 1 | T8: 1 | U8: 1 | V8: 1 | W8: 1 | X8: 1
B9: Unit | C9: Other staff | E9: 1 | F9: 1 | G9: 1 | H9: 1 | I9: 1 | J9: 1 | K9: 1 | L9: 1 | M9: 1 | N9: 1 | O9: 1 | P9: 1 | Q9: 1 | R9: 1 | S9: 1 | T9: 1 | U9: 1 | V9: 1 | W9: 1 | X9: 1
B10: Unit | C10: Other staff | E10: 1 | F10: 1 | G10: 1 | H10: 1 | I10: 1 | J10: 1 | K10: 1 | L10: 1 | M10: 1 | N10: 1 | O10: 1 | P10: 1 | Q10: 1 | R10: 1 | S10: 1 | T10: 1 | U10: 1 | V10: 1 | W10: 1 | X10: 1
B11: Unit | C11: Other staff | E11: 1 | F11: 1 | G11: 1 | H11: 1 | I11: 1 | J11: 1 | K11: 1 | L11: 1 | M11: 1 | N11: 1 | O11: 1 | P11: 1 | Q11: 1 | R11: 1 | S11: 1 | T11: 1 | U11: 1 | V11: 1 | W11: 1 | X11: 1
B12: Unit | C12: Other staff | E12: 1 | F12: 1 | G12: 1 | H12: 1 | I12: 1 | J12: 1 | K12: 1 | L12: 1 | M12: 1 | N12: 1 | O12: 1 | P12: 1 | Q12: 1 | R12: 1 | S12: 1 | T12: 1 | U12: 1 | V12: 1 | W12: 1 | X12: 1
B13: Unit | C13: Other staff | E13: 1 | F13: 1 | G13: 1 | H13: 1 | I13: 1 | J13: 1 | K13: 1 | L13: 1 | M13: 1 | N13: 1 | O13: 1 | P13: 1 | Q13: 1 | R13: 1 | S13: 1 | T13: 1 | U13: 1 | V13: 1 | W13: 1 | X13: 1
B14: Unit | C14: Other staff | E14: 1 | F14: 1 | G14: 1 | H14: 1 | I14: 1 | J14: 1 | K14: 1 | L14: 1 | M14: 1 | N14: 1 | O14: 1 | P14: 1 | Q14: 1 | R14: 1 | S14: 1 | T14: 1 | U14: 1 | V14: 1 | W14: 1 | X14: 1
B15: Unit | C15: Other staff | E15: 1 | F15: 1 | G15: 1 | H15: 1 | I15: 1 | J15: 1 | K15: 1 | L15: 1 | M15: 1 | N15: 1 | O15: 1 | P15: 1 | Q15: 1 | R15: 1 | S15: 1 | T15: 1 | U15: 1 | V15: 1 | W15: 1 | X15: 1
B16: Unit | C16: Other staff | E16: 1 | F16: 1 | G16: 1 | H16: 1 | I16: 1 | J16: 1 | K16: 1 | L16: 1 | M16: 1 | N16: 1 | O16: 1 | P16: 1 | Q16: 1 | R16: 1 | S16: 1 | T16: 1 | U16: 1 | V16: 1 | W16: 1 | X16: 1
... B23: Unit | C23: Other staff | E23: 1 | F23: 1 | G23: 1 | H23: 1 | I23: 1 | J23: 1 | K23: 1 | L23: 1 | M23: 1 | N23: 1 | O23: 1 | P23: 1 | Q23: 1 | R23: 1 | S23: 1 | T23: 1 | U23: 1 | V23: 1 | W23: 1 | X23: 1
A24: Total Head Count | E24: =SUM(E5:E23) -> 19 | F24: =SUM(F5:F23) -> 19 | G24: =SUM(G5:G23) -> 19 | H24: =SUM(H5:H23) -> 19 | I24: =SUM(I5:I23) -> 19 | J24: =SUM(J5:J23) -> 19 | K24: =SUM(K5:K23) -> 19 | L24: =SUM(L5:L23) -> 19 | ... X24: =SUM(X5:X23) -> 19
A27: Variable | B27: Value | C27: Position Salary | D27: Annual Salary | E27: Year 1 | F27: Year 2 | G27: Year 3 | H27: Year 4 | I27: Year 5 | J27: Year 6 | K27: Year 7 | L27: Year 8 | M27: Year 9 | N27: Year 10 | O27: Year 11 | P27: Year 12 | Q27: Year 13 | R27: Year 14 | S27: Year 15 | T27: Year 16 | U27: Year 17 | V27: Year 18 | W27: Year 19 | X27: Year 20
B28: US$ | C28: =C5 -> Program Manager | D28: =1500*12 -> 18000 | E28: =E5*$D28 -> 18000 | F28: =F5*$D28 -> 18000 | G28: =G5*$D28 -> 18000 | H28: =H5*$D28 -> 18000 | I28: =I5*$D28 -> 18000 | J28: =J5*$D28 -> 18000 | K28: =K5*$D28 -> 18000 | L28: =L5*$D28 -> 18000 | ... X28: =X5*$D28 -> 18000
B29: US$ | C29: =C6 -> Logistic Manager | D29: 15000 | E29: =E6*$D29 -> 15000 | F29: =F6*$D29 -> 15000 | G29: =G6*$D29 -> 15000 | H29: =H6*$D29 -> 15000 | I29: =I6*$D29 -> 15000 | J29: =J6*$D29 -> 15000 | K29: =K6*$D29 -> 15000 | L29: =L6*$D29 -> 15000 | ... X29: =X6*$D29 -> 15000
B30: US$ | C30: =C7 -> Other staff | D30: 10000 | E30: =E7*$D30 -> 10000 | F30: =F7*$D30 -> 10000 | G30: =G7*$D30 -> 10000 | H30: =H7*$D30 -> 10000 | I30: =I7*$D30 -> 10000 | J30: =J7*$D30 -> 10000 | K30: =K7*$D30 -> 10000 | L30: =L7*$D30 -> 10000 | ... X30: =X7*$D30 -> 10000
B31: US$ | C31: =C8 -> Other staff | D31: 7000 | E31: =E8*$D31 -> 7000 | F31: =F8*$D31 -> 7000 | G31: =G8*$D31 -> 7000 | H31: =H8*$D31 -> 7000 | I31: =I8*$D31 -> 7000 | J31: =J8*$D31 -> 7000 | K31: =K8*$D31 -> 7000 | L31: =L8*$D31 -> 7000 | ... X31: =X8*$D31 -> 7000
B32: US$ | C32: =C9 -> Other staff | D32: 5000 | E32: =E9*$D32 -> 5000 | F32: =F9*$D32 -> 5000 | G32: =G9*$D32 -> 5000 | H32: =H9*$D32 -> 5000 | I32: =I9*$D32 -> 5000 | J32: =J9*$D32 -> 5000 | K32: =K9*$D32 -> 5000 | L32: =L9*$D32 -> 5000 | ... X32: =X9*$D32 -> 5000
B33: US$ | C33: =C10 -> Other staff | D33: 5000 | E33: =E10*$D33 -> 5000 | F33: =F10*$D33 -> 5000 | G33: =G10*$D33 -> 5000 | H33: =H10*$D33 -> 5000 | I33: =I10*$D33 -> 5000 | J33: =J10*$D33 -> 5000 | K33: =K10*$D33 -> 5000 | L33: =L10*$D33 -> 5000 | ... X33: =X10*$D33 -> 5000
B34: US$ | C34: =C11 -> Other staff | D34: 5000 | E34: =E11*$D34 -> 5000 | F34: =F11*$D34 -> 5000 | G34: =G11*$D34 -> 5000 | H34: =H11*$D34 -> 5000 | I34: =I11*$D34 -> 5000 | J34: =J11*$D34 -> 5000 | K34: =K11*$D34 -> 5000 | L34: =L11*$D34 -> 5000 | ... X34: =X11*$D34 -> 5000
B35: US$ | C35: =C12 -> Other staff | D35: 5000 | E35: =E12*$D35 -> 5000 | F35: =F12*$D35 -> 5000 | G35: =G12*$D35 -> 5000 | H35: =H12*$D35 -> 5000 | I35: =I12*$D35 -> 5000 | J35: =J12*$D35 -> 5000 | K35: =K12*$D35 -> 5000 | L35: =L12*$D35 -> 5000 | ... X35: =X12*$D35 -> 5000
B36: US$ | C36: =C13 -> Other staff | D36: 5000 | E36: =E13*$D36 -> 5000 | F36: =F13*$D36 -> 5000 | G36: =G13*$D36 -> 5000 | H36: =H13*$D36 -> 5000 | I36: =I13*$D36 -> 5000 | J36: =J13*$D36 -> 5000 | K36: =K13*$D36 -> 5000 | L36: =L13*$D36 -> 5000 | ... X36: =X13*$D36 -> 5000
B37: US$ | C37: =C14 -> Other staff | D37: 5000 | E37: =E14*$D37 -> 5000 | F37: =F14*$D37 -> 5000 | G37: =G14*$D37 -> 5000 | H37: =H14*$D37 -> 5000 | I37: =I14*$D37 -> 5000 | J37: =J14*$D37 -> 5000 | K37: =K14*$D37 -> 5000 | L37: =L14*$D37 -> 5000 | ... X37: =X14*$D37 -> 5000
B38: US$ | C38: =C15 -> Other staff | D38: 5000 | E38: =E15*$D38 -> 5000 | F38: =F15*$D38 -> 5000 | G38: =G15*$D38 -> 5000 | H38: =H15*$D38 -> 5000 | I38: =I15*$D38 -> 5000 | J38: =J15*$D38 -> 5000 | K38: =K15*$D38 -> 5000 | L38: =L15*$D38 -> 5000 | ... X38: =X15*$D38 -> 5000
B39: US$ | C39: =C16 -> Other staff | D39: 5000 | E39: =E16*$D39 -> 5000 | F39: =F16*$D39 -> 5000 | G39: =G16*$D39 -> 5000 | H39: =H16*$D39 -> 5000 | I39: =I16*$D39 -> 5000 | J39: =J16*$D39 -> 5000 | K39: =K16*$D39 -> 5000 | L39: =L16*$D39 -> 5000 | ... X39: =X16*$D39 -> 5000
B40: US$ | C40: =C17 -> Other staff | D40: 5000 | E40: =E17*$D40 -> 5000 | F40: =F17*$D40 -> 5000 | G40: =G17*$D40 -> 5000 | H40: =H17*$D40 -> 5000 | I40: =I17*$D40 -> 5000 | J40: =J17*$D40 -> 5000 | K40: =K17*$D40 -> 5000 | L40: =L17*$D40 -> 5000 | ... X40: =X17*$D40 -> 5000
... B46: US$ | C46: =C23 -> Other staff | D46: 5000 | E46: =E23*$D46 -> 5000 | F46: =F23*$D46 -> 5000 | G46: =G23*$D46 -> 5000 | H46: =H23*$D46 -> 5000 | I46: =I23*$D46 -> 5000 | J46: =J23*$D46 -> 5000 | K46: =K23*$D46 -> 5000 | L46: =L23*$D46 -> 5000 | ... X46: =X23*$D46 -> 5000
A47: Total Head Count | E47: =SUM(E28:E46) -> 125000 | F47: =SUM(F28:F46) -> 125000 | G47: =SUM(G28:G46) -> 125000 | H47: =SUM(H28:H46) -> 125000 | I47: =SUM(I28:I46) -> 125000 | J47: =SUM(J28:J46) -> 125000 | K47: =SUM(K28:K46) -> 125000 | L47: =SUM(L28:L46) -> 125000 | ... X47: =SUM(X28:X46) -> 125000

Sheet OPEX
A1: Opex
A4: Variable | B4: Value | C4: Description (with units) | D4: Notes | E4: Year 1 | F4: Year 2 | G4: Year 3 | H4: Year 4 | I4: Year 5 | J4: Year 6 | K4: Year 7 | L4: Year 8 | M4: Year 9 | N4: Year 10 | O4: Year 11 | P4: Year 12 | Q4: Year 13 | R4: Year 14 | S4: Year 15 | T4: Year 16 | U4: Year 17 | V4: Year 18 | W4: Year 19 | X4: Year 20 | Y4: Year 21 | Z4: Year 22
B5: US$ | C5: Plantation Maintenance | D5: 50 | E5: =Assumptions!E8*$D5 -> 100000 | F5: =Assumptions!F8*$D5 -> 200000 | G5: =Assumptions!G8*$D5 -> 200000 | H5: =Assumptions!H8*$D5 -> 200000 | I5: =Assumptions!I8*$D5 -> 200000 | J5: =Assumptions!J8*$D5 -> 200000 | K5: =Assumptions!K8*$D5 -> 200000 | L5: =Assumptions!L8*$D5 -> 200000 | ... Z5: =Assumptions!Z8*$D5 -> 0
B6: US$ | C6: Staff Salaries | E6: =HR!E47 -> 125000 | F6: =HR!F47 -> 125000 | G6: =HR!G47 -> 125000 | H6: =HR!H47 -> 125000 | I6: =HR!I47 -> 125000 | J6: =HR!J47 -> 125000 | K6: =HR!K47 -> 125000 | L6: =HR!L47 -> 125000 | ... Z6: =HR!Z47 -> 0
B7: US$ | C7: Monitoring & Reporting | E7: 50000
B8: US$ | C8: Community Engagement | E8: 20000
B9: US$ | C9: Admin & Overheads | E9: 50000
B10: US$ | C10: Carbon Costs | E10: ='Carbon Costs'!E11 -> 160000 | F10: ='Carbon Costs'!F11 -> 0 | G10: ='Carbon Costs'!G11 -> 0 | H10: ='Carbon Costs'!H11 -> 0 | I10: ='Carbon Costs'!I11 -> 160000 | J10: ='Carbon Costs'!J11 -> 0 | K10: ='Carbon Costs'!K11 -> 0 | L10: ='Carbon Costs'!L11 -> 0 | ... Z10: ='Carbon Costs'!Z11 -> 0
B11: US$ | C11: Transportation
B12: US$ | C12: Communication & PR
B13: US$ | C13: Other
B14: US$ | C14: Other
B15: US$ | C15: Other
B16: US$ | C16: Other
B17: US$ | C17: Other
B18: US$ | C18: Other
B19: US$ | C19: TOTAL | E19: =SUM(E5:E18) -> 505000 | F19: =SUM(F5:F18) -> 325000 | G19: =SUM(G5:G18) -> 325000 | H19: =SUM(H5:H18) -> 325000 | I19: =SUM(I5:I18) -> 485000 | J19: =SUM(J5:J18) -> 325000 | K19: =SUM(K5:K18) -> 325000 | L19: =SUM(L5:L18) -> 325000 | ... Z19: =SUM(Z5:Z18) -> 0
A24: Notes

Sheet Carbon Costs
A1: Carbon Costs
A4: Variable | B4: Value | C4: Description (with units) | D4: Notes | E4: Year 1 | F4: Year 2 | G4: Year 3 | H4: Year 4 | I4: Year 5 | J4: Year 6 | K4: Year 7 | L4: Year 8 | M4: Year 9 | N4: Year 10 | O4: Year 11 | P4: Year 12 | Q4: Year 13 | R4: Year 14 | S4: Year 15 | T4: Year 16 | U4: Year 17 | V4: Year 18 | W4: Year 19 | X4: Year 20 | Y4: Year 21 | Z4: Year 22
B5: US$ | C5: GS fees | E5: 10000 | I5: 10000 | N5: 10000 | S5: 10000 | X5: 10000
B6: US$ | C6: VVBs | E6: 50000 | I6: 50000 | N6: 50000 | S6: 50000 | X6: 50000
B7: US$ | C7: Baseline & other surveys | E7: 100000 | I7: 100000 | N7: 100000 | S7: 100000 | X7: 100000
B8: US$ | C8: Share of Proceeds
B9: US$ | C9: Other
B10: US$ | C10: Other
B11: US$ | C11: TOTAL | E11: =SUM(E5:E10) -> 160000 | F11: =SUM(F5:F10) -> 0 | G11: =SUM(G5:G10) -> 0 | H11: =SUM(H5:H10) -> 0 | I11: =SUM(I5:I10) -> 160000 | J11: =SUM(J5:J10) -> 0 | K11: =SUM(K5:K10) -> 0 | L11: =SUM(L5:L10) -> 0 | ... Z11: =SUM(Z5:Z10) -> 0
A16: Notes

Sheet Revenue
A1: Revenue
A4: Variable | B4: Value | C4: Description (with units) | D4: Notes | E4: Year 1 | F4: Year 2 | G4: Year 3 | H4: Year 4 | I4: Year 5 | J4: Year 6 | K4: Year 7 | L4: Year 8 | M4: Year 9 | N4: Year 10 | O4: Year 11 | P4: Year 12 | Q4: Year 13 | R4: Year 14 | S4: Year 15 | T4: Year 16 | U4: Year 17 | V4: Year 18 | W4: Year 19 | X4: Year 20 | Y4: Year 21 | Z4: Year 22 | AA4: Total
A5: CR_annualized | B5: t CO2e/year | C5: Production: Annualized carbon dioxide removals | D5: From Eq30 | E5: =Eq30_Carbon_removals!E11 -> 15022.679 | F5: =Eq30_Carbon_removals!F11 -> 54135.682 | G5: =Eq30_Carbon_removals!G11 -> 125925.12 | H5: =Eq30_Carbon_removals!H11 -> 156117.98 | I5: =Eq30_Carbon_removals!I11 -> 213866.99 | J5: =Eq30_Carbon_removals!J11 -> 199763.2 | K5: =Eq30_Carbon_removals!K11 -> 258373.36 | L5: =Eq30_Carbon_removals!L11 -> 293713.69 | ... X5: =Eq30_Carbon_removals!X11 -> 78540.929
B6: t CO2e/year | C6: Validation & sale | G6: =E5 -> 15022.679 | H6: =F5 -> 54135.682 | I6: =G5 -> 125925.12 | J6: =H5 -> 156117.98 | K6: =I5 -> 213866.99 | L6: =J5 -> 199763.2 | M6: =K5 -> 258373.36 | N6: =L5 -> 293713.69 | ... Z6: =X5 -> 78540.929
B7: US$ | C7: Price per tCO2e | G7: =Assumptions!B11 -> 10 | H7: =G7*(1+Assumptions!$B12) -> 10.5 | I7: =H7*(1+Assumptions!$B12) -> 11.025 | J7: =I7*(1+Assumptions!$B12) -> 11.57625 | K7: =J7*(1+Assumptions!$B12) -> 12.155063 | L7: =K7*(1+Assumptions!$B12) -> 12.762816 | M7: =L7*(1+Assumptions!$B12) -> 13.400956 | N7: =M7*(1+Assumptions!$B12) -> 14.071004 | O7: =N7*(1+Assumptions!$B12) -> 14.774554 | ... Z7: =Y7*(1+Assumptions!$B12) -> 25.269502
B8: US$ | C8: Carbon sales revenues | G8: =G7*G6 -> 150226.79 | H8: =H7*H6 -> 568424.66 | I8: =I7*I6 -> 1388324.4 | J8: =J7*J6 -> 1807260.8 | K8: =K7*K6 -> 2599566.6 | L8: =L7*L6 -> 2549540.9 | M8: =M7*M6 -> 3462450.1 | N8: =N7*N6 -> 4132846.5 | ... Z8: =Z7*Z6 -> 1984690.2 | AA8: =SUM(G8:Z8) -> 52046537
A16: Notes

Sheet Impact
A1: Impact
A4: Variable | B4: Value | C4: Description (with units) | D4: Average | E4: Year 1 | F4: Year 2 | G4: Year 3 | H4: Year 4 | I4: Year 5 | J4: Year 6 | K4: Year 7 | L4: Year 8 | M4: Year 9 | N4: Year 10 | O4: Year 11 | P4: Year 12 | Q4: Year 13 | R4: Year 14 | S4: Year 15 | T4: Year 16 | U4: Year 17 | V4: Year 18 | W4: Year 19 | X4: Year 20
B5: km | C5: Total km of riverbanks stabilised | E5: =Assumptions!E7 -> 500 | F5: =E5+Assumptions!F7 -> 1000 | G5: =F5+Assumptions!G7 -> 1000 | H5: =G5+Assumptions!H7 -> 1000 | I5: =H5+Assumptions!I7 -> 1000 | J5: =I5+Assumptions!J7 -> 1000 | K5: =J5+Assumptions!K7 -> 1000 | L5: =K5+Assumptions!L7 -> 1000 | M5: =L5+Assumptions!M7 -> 1000 | ... X5: =W5+Assumptions!X7 -> 1000
B6: ha | C6: Total hectares planted | E6: =Assumptions!E8 -> 2000 | F6: =Assumptions!F8 -> 4000 | G6: =Assumptions!G8 -> 4000 | H6: =Assumptions!H8 -> 4000 | I6: =Assumptions!I8 -> 4000 | J6: =Assumptions!J8 -> 4000 | K6: =Assumptions!K8 -> 4000 | L6: =Assumptions!L8 -> 4000 | ... X6: =Assumptions!X8 -> 4000
B7: units | C7: Total number of bamboo plants | E7: =E6*Assumptions!$B17 -> 1000000 | F7: =F6*Assumptions!$B17 -> 2000000 | G7: =G6*Assumptions!$B17 -> 2000000 | H7: =H6*Assumptions!$B17 -> 2000000 | I7: =I6*Assumptions!$B17 -> 2000000 | J7: =J6*Assumptions!$B17 -> 2000000 | K7: =K6*Assumptions!$B17 -> 2000000 | L7: =L6*Assumptions!$B17 -> 2000000 | ... X7: =X6*Assumptions!$B17 -> 2000000
B8: ha | C8: Total hectares agricultural fields protected from flood rush | E8: =E6*Assumptions!$B23 -> 20000 | F8: =F6*Assumptions!$B23 -> 40000 | G8: =G6*Assumptions!$B23 -> 40000 | H8: =H6*Assumptions!$B23 -> 40000 | I8: =I6*Assumptions!$B23 -> 40000 | J8: =J6*Assumptions!$B23 -> 40000 | K8: =K6*Assumptions!$B23 -> 40000 | L8: =L6*Assumptions!$B23 -> 40000 | ... X8: =X6*Assumptions!$B23 -> 40000
B9: t CO2e/year | C9: Total tCO2e produced | E9: =Eq34_Annualized!E8 -> 15022.679 | F9: =Eq34_Annualized!F8 -> 54135.682 | G9: =Eq34_Annualized!G8 -> 125925.12 | H9: =Eq34_Annualized!H8 -> 156117.98 | I9: =Eq34_Annualized!I8 -> 213866.99 | J9: =Eq34_Annualized!J8 -> 199763.2 | K9: =Eq34_Annualized!K8 -> 258373.36 | L9: =Eq34_Annualized!L8 -> 293713.69 | ... X9: =Eq34_Annualized!X8 -> 78540.929
B10: t CO2e/ha | C10: tCO2e per ha | D10: =AVERAGE(E10:X10) -> 40.332396 | E10: =E9/E6 -> 7.5113396 | F10: =F9/F6 -> 13.53392 | G10: =G9/G6 -> 31.481279 | H10: =H9/H6 -> 39.029496 | I10: =I9/I6 -> 53.466748 | J10: =J9/J6 -> 49.940801 | K10: =K9/K6 -> 64.593339 | L10: =L9/L6 -> 73.428421 | ... X10: =X9/X6 -> 19.635232
B11: households | C11: Number of households benefitting from access to bamboo poles
C12: Other
C13: Other
A17: Notes

Sheet Eq4_CWP_woody
A1: Eq4: Total woody biomass carbon per hectare (t C/ha)
A4: Variable | B4: Value | C4: Description (with units) | D4: Notes | E4: Year 1 | F4: Year 2 | G4: Year 3 | H4: Year 4 | I4: Year 5 | J4: Year 6 | K4: Year 7 | L4: Year 8 | M4: Year 9 | N4: Year 10 | O4: Year 11 | P4: Year 12 | Q4: Year 13 | R4: Year 14 | S4: Year 15 | T4: Year 16 | U4: Year 17 | V4: Year 18 | W4: Year 19 | X4: Year 20
A5: CWP-woody-AB,t | C5: Aboveground woody biomass (t C/ha) | D5: Field measurement/allometry | E5: =Biomass!E6 -> 0.9 | F5: =Biomass!E7 -> 4.2 | G5: =Biomass!E8 -> 16.5 | H5: =Biomass!E9 -> 31.5 | I5: =Biomass!E10 -> 52.5 | J5: =Biomass!E11 -> 70 | K5: =Biomass!E12 -> 94.5 | L5: =Biomass!E13 -> 122.5 | M5: =Biomass!E14 -> 140 | N5: =Biomass!E15 -> 157.5 | O5: =Biomass!E16 -> 175 | P5: =Biomass!E17 -> 192.5 | Q5: =Biomass!E18 -> 210 | R5: =Biomass!E19 -> 227.5 | S5: =Biomass!E20 -> 245 | T5: =Biomass!E21 -> 262.5 | U5: =Biomass!E22 -> 273 | V5: =Biomass!E23 -> 280 | W5: =Biomass!E24 -> 287 | X5: =Biomass!E25 -> 294
A6: R | C6: Root to shoot ratio (unitless) | D6: IPCC default tropical | E6: =Biomass!A30 -> 0.24
C7: Belowground woody biomass (t C/ha) | D7: Calculated | E7: =E5*$E6 -> 0.216 | F7: =F5*$E6 -> 1.008 | G7: =G5*$E6 -> 3.96 | H7: =H5*$E6 -> 7.56 | I7: =I5*$E6 -> 12.6 | J7: =J5*$E6 -> 16.8 | K7: =K5*$E6 -> 22.68 | L7: =L5*$E6 -> 29.4 | ... X7: =X5*$E6 -> 70.56
A9: CWP-woody,t | C9: Total woody biomass carbon per hectare (t C/ha) | E9: =E5*(1+$E6) -> 1.116 | F9: =F5*(1+$E6) -> 5.208 | G9: =G5*(1+$E6) -> 20.46 | H9: =H5*(1+$E6) -> 39.06 | I9: =I5*(1+$E6) -> 65.1 | J9: =J5*(1+$E6) -> 86.8 | K9: =K5*(1+$E6) -> 117.18 | L9: =L5*(1+$E6) -> 151.9 | ... X9: =X5*(1+$E6) -> 364.56
A16: Notes
A17: This calculates cumulative carbon changes since project baseline (t=0)

Sheet Eq6_CWP_herb
A1: Eq6: Non-woody biomass carbon per hectare (t C/ha)
A4: Variable | B4: Value | C4: Description (with units) | D4: Notes | E4: Year 1 | F4: Year 2 | G4: Year 3 | H4: Year 4 | I4: Year 5 | J4: Year 6 | K4: Year 7 | L4: Year 8 | M4: Year 9 | N4: Year 10 | O4: Year 11 | P4: Year 12 | Q4: Year 13 | R4: Year 14 | S4: Year 15 | T4: Year 16 | U4: Year 17 | V4: Year 18 | W4: Year 19 | X4: Year 20
A5: DMWP-herb,t | B5: t d.m./ha | C5: Non-woody biomass dry matter | D5: Estimated as 4% of woody biomass | E5: 3 | F5: 3 | G5: 2 | H5: 2 | I5: 1.5 | J5: 1 | K5: 1 | L5: 0.75 | M5: 0.75 | N5: 0.5 | O5: 0.5 | P5: 0.4 | Q5: 0.4 | R5: 0.3 | S5: 0.3 | T5: 0.2 | U5: 0.2 | V5: 0.1 | W5: 0.1 | X5: 0.1 | Y5: Not sure this makes sense
A6: CF | B6: t C/t d.m. | C6: Carbon fraction of dry biomass | D6: IPCC default | E6: =Biomass!$A28 -> 0.47
A8: CWP-herb,t | C8: Non-woody biomass carbon per hectare (t C/ha) | E8: =E5*$E6 -> 1.41 | F8: =F5*$E6 -> 1.41 | G8: =G5*$E6 -> 0.94 | H8: =H5*$E6 -> 0.94 | I8: =I5*$E6 -> 0.705 | J8: =J5*$E6 -> 0.47 | K8: =K5*$E6 -> 0.47 | L8: =L5*$E6 -> 0.3525 | ... X8: =X5*$E6 -> 0.047
A16: Notes
A17: This equation is used to estimate the carbon stored in herbaceous (non-woody) biomass on a per-hectare basis. It is part of the broader calculation of total biomass carbon in the project scenario.
A18: This value feeds into Equation (2), which sums all biomass pools (woody, herbaceous, dead wood, litter) to calculate total biomass carbon change.
A20: Bamboo plantations progressively suppress understory vegetation through multiple mechanisms: 1. Allelopathic Suppression: * Chemical inhibition: Bamboo produces allelopathic compounds (natural herbicides) * Research evidence: University of Tennessee states: "Many bamboo species produce allelopathic compounds, which prevent other plant species from living in the understory of a bamboo thicket" 2. Physical Suppression: * Dense canopy: Bamboo creates heavy shading * Thick litter layer: Fallen leaves create physical barrier * Light competition: Minimal light reaches ground level Realistic Bambusa balcooa Non-woody Biomass Pattern: Years 1-2: 2.0-3.0 t d.m./ha (open canopy, weeds/grasses establish) Years 3-5: 1.0-2.0 t d.m./ha (canopy closing, competition increasing) Years 6-10: 0.3-1.0 t d.m./ha (heavy shading, allelopathy active) Years 11-20: 0.1-0.5 t d.m./ha (minimal understory, dominated by litter)

Sheet Eq8_CWP_DW
A1: Eq8: Dead wood carbon per hectare (t C/ha)
A4: Variable | B4: Value | C4: Description (with units) | D4: Notes | E4: Year 1 | F4: Year 2 | G4: Year 3 | H4: Year 4 | I4: Year 5 | J4: Year 6 | K4: Year 7 | L4: Year 8 | M4: Year 9 | N4: Year 10 | O4: Year 11 | P4: Year 12 | Q4: Year 13 | R4: Year 14 | S4: Year 15 | T4: Year 16 | U4: Year 17 | V4: Year 18 | W4: Year 19 | X4: Year 20
A5: BSDW,t | B5: t d.m./ha | C5: Standing dead wood biomass | D5: See note below | E5: =2%*Eq4_CWP_woody!E5 -> 0.018 | F5: =2%*Eq4_CWP_woody!F5 -> 0.084 | G5: =2%*Eq4_CWP_woody!G5 -> 0.33 | H5: =2%*Eq4_CWP_woody!H5 -> 0.63 | I5: =2%*Eq4_CWP_woody!I5 -> 1.05 | J5: =8%*Eq4_CWP_woody!J5 -> 5.6 | K5: =8%*Eq4_CWP_woody!K5 -> 7.56 | L5: =8%*Eq4_CWP_woody!L5 -> 9.8 | M5: =8%*Eq4_CWP_woody!M5 -> 11.2 | N5: =8%*Eq4_CWP_woody!N5 -> 12.6 | O5: =12%*Eq4_CWP_woody!O5 -> 21 | P5: =12%*Eq4_CWP_woody!P5 -> 23.1 | Q5: =12%*Eq4_CWP_woody!Q5 -> 25.2 | R5: =12%*Eq4_CWP_woody!R5 -> 27.3 | S5: =12%*Eq4_CWP_woody!S5 -> 29.4 | T5: =12%*Eq4_CWP_woody!T5 -> 31.5 | U5: =12%*Eq4_CWP_woody!U5 -> 32.76 | V5: =12%*Eq4_CWP_woody!V5 -> 33.6 | ... X5: =12%*Eq4_CWP_woody!X5 -> 35.28
A6: BLDW,t | B6: t d.m./ha | C6: Lying dead wood biomass (t d.m./ha) | D6: See note below | E6: =Eq4_CWP_woody!E5*1% -> 0.009 | F6: =Eq4_CWP_woody!F5*1% -> 0.042 | G6: =Eq4_CWP_woody!G5*1% -> 0.165 | H6: =Eq4_CWP_woody!H5*1% -> 0.315 | I6: =Eq4_CWP_woody!I5*1% -> 0.525 | J6: =Eq4_CWP_woody!J5*3% -> 2.1 | K6: =Eq4_CWP_woody!K5*3% -> 2.835 | L6: =Eq4_CWP_woody!L5*3% -> 3.675 | M6: =Eq4_CWP_woody!M5*3% -> 4.2 | N6: =Eq4_CWP_woody!N5*3% -> 4.725 | O6: =Eq4_CWP_woody!O5*5% -> 8.75 | P6: =Eq4_CWP_woody!P5*5% -> 9.625 | Q6: =Eq4_CWP_woody!Q5*5% -> 10.5 | R6: =Eq4_CWP_woody!R5*5% -> 11.375 | S6: =Eq4_CWP_woody!S5*5% -> 12.25 | T6: =Eq4_CWP_woody!T5*5% -> 13.125 | U6: =Eq4_CWP_woody!U5*5% -> 13.65 | V6: =Eq4_CWP_woody!V5*5% -> 14 | ... X6: =Eq4_CWP_woody!X5*5% -> 14.7
A7: CF | B7: t C/t d.m. | C7: Carbon fraction of dry biomass | D7: IPCC default | E7: =Biomass!A28 -> 0.47
A9: CWP-DW,t | B9: t C/ha | C9: Dead wood carbon per hectare | E9: =(E5+E6)*$E7 -> 0.01269 | F9: =(F5+F6)*$E7 -> 0.05922 | G9: =(G5+G6)*$E7 -> 0.23265 | H9: =(H5+H6)*$E7 -> 0.44415 | I9: =(I5+I6)*$E7 -> 0.74025 | J9: =(J5+J6)*$E7 -> 3.619 | K9: =(K5+K6)*$E7 -> 4.88565 | L9: =(L5+L6)*$E7 -> 6.33325 | ... X9: =(X5+X6)*$E7 -> 23.4906
A16: Notes
A17: Unlike managed plantations, unmanaged stands will develop significant dead wood pools (see: https://pmc.ncbi.nlm.nih.gov/articles/PMC4165839/) Dead Wood as % of Live Biomass (Dry Matter Basis) Standing Dead Wood (BSDW,t) as % of Live Biomass: Time Period Percentage Range Reasoning Years 1-5 1-3% Minimal natural mortality in young stands Years 6-10 3-8% First cohort senescence beginning Years 11-15 5-12% Peak mortality phase, but excluding P. makinoi anomaly Years 16-20 4-10% Steady state (closer to P. pubescens 10.5% than P. makinoi 52%) Lying Dead Wood (BLDW,t) as % of Live Biomass: Time Period Percentage Range Reasoning Years 1-5 0.5-2% Minimal fallen material Years 6-10 2-4% Some natural fall, rapid decomposition in riparian zone Years 11-15 3-6% Fallen dead culms accumulating Years 16-20 2-5% Balanced by faster tropical decomposition Total Dead Wood as % of Live Biomass: Time Period Combined Range Years 1-5 1.5-5% Years 6-10 5-12% Years 11-15 8-18% Years 16-20 6-15%
A18: Realistic BSDW,t (Standing Dead Wood) Pattern:
A19: Years 1-5: 0-2% of live biomass (minimal mortality)
A20: Years 6-10: 5-15% of live biomass (first cohort dying)
A21: Years 11-15: 10-20% of live biomass (steady-state mortality)
A22: Years 16-20: 15-25% of live biomass (multiple cohorts overlapping)
A23: Realistic BLDW,t (Lying Dead Wood) Pattern:
A24: Years 1-5: 0-1% of live biomass
A25: Years 6-10: 2-8% of live biomass (fallen culms accumulating)
A26: Years 11-15: 5-12% of live biomass
A27: Years 16-20: 8-15% of live biomass (but balanced by decomposition)

Sheet Eq10_CWP_LI
A1: Eq10: Litter carbon per hectare (t C/ha)
A4: Variable | B4: Value | C4: Description (with units) | D4: Notes | E4: Year 1 | F4: Year 2 | G4: Year 3 | H4: Year 4 | I4: Year 5 | J4: Year 6 | K4: Year 7 | L4: Year 8 | M4: Year 9 | N4: Year 10 | O4: Year 11 | P4: Year 12 | Q4: Year 13 | R4: Year 14 | S4: Year 15 | T4: Year 16 | U4: Year 17 | V4: Year 18 | W4: Year 19 | X4: Year 20
A5: DMWP-LI,t | C5: Litter dry matter (t d.m./ha) | D5: Steady state litter accumulation | E5: 1.5 | F5: 2 | G5: 2.5 | H5: 2.8 | I5: 2.9 | J5: 3 | K5: 3.1 | L5: 3.2 | M5: 3.3 | N5: 3.4 | O5: 3.5 | P5: 3.6 | Q5: 3.7 | R5: 3.8 | S5: 3.9 | T5: 4 | U5: 4.1 | V5: 4.2 | W5: 4.3 | X5: 4.4
A6: CF | C6: Carbon fraction of dry biomass (t C/t d.m.) | D6: IPCC default | E6: =Biomass!A28 -> 0.47
A8: CWP-LI,t | C8: Litter carbon per hectare (t C/ha) | E8: =E5*$E6 -> 0.705 | F8: =F5*$E6 -> 0.94 | G8: =G5*$E6 -> 1.175 | H8: =H5*$E6 -> 1.316 | I8: =I5*$E6 -> 1.363 | J8: =J5*$E6 -> 1.41 | K8: =K5*$E6 -> 1.457 | L8: =L5*$E6 -> 1.504 | ... X8: =X5*$E6 -> 2.068
A16: Notes
A17: Limited Scientific Data Available: From the Taiwan study (the only bamboo litter data I found): P. makinoi (26 years): ~2 Mg C/ha litter ÷ 0.47 CF = 4.3 t d.m./ha P. pubescens (41 years): ~2 Mg C/ha litter ÷ 0.47 CF = 4.3 t d.m./ha Reference forest: 3.91 Mg C/ha ÷ 0.47 = 8.3 t d.m./ha But this is from post-landslide recovery sites, not typical bamboo plantations.

Sheet Eq11_Delta_SOC
A1: Eq11: Soil organic carbon stock change (t C)
A4: Variable | B4: Value | C4: Description (with units) | D4: Notes | E4: Year 1 | F4: Year 2 | G4: Year 3 | H4: Year 4 | I4: Year 5 | J4: Year 6 | K4: Year 7 | L4: Year 8 | M4: Year 9 | N4: Year 10 | O4: Year 11 | P4: Year 12 | Q4: Year 13 | R4: Year 14 | S4: Year 15 | T4: Year 16 | U4: Year 17 | V4: Year 18 | W4: Year 19 | X4: Year 20
A5: A | B5: ha | C5: Project area | D5: GIS measurement | E5: =Assumptions!E8 -> 2000 | F5: =Assumptions!F8 -> 4000 | G5: =Assumptions!G8 -> 4000 | H5: =Assumptions!H8 -> 4000 | I5: =Assumptions!I8 -> 4000 | J5: =Assumptions!J8 -> 4000 | K5: =Assumptions!K8 -> 4000 | L5: =Assumptions!L8 -> 4000 | ... X5: =Assumptions!X8 -> 4000
A6: CWP-SOC,t=0 | B6: t C/ha | C6: Initial soil carbon stock | D6: Baseline soil carbon | E6: 47 | F6: 47 | G6: 47 | H6: 47 | I6: 47 | J6: 47 | K6: 47 | L6: 47 | M6: 47 | N6: 47 | O6: 47 | P6: 47 | Q6: 47 | R6: 47 | S6: 47 | T6: 47 | U6: 47 | V6: 47 | W6: 47 | X6: 47 | Y6: Verify Assumptions!
A7: CWP-SOC,t | B7: t C/ha | C7: Soil carbon stock at year t | D7: Baseline + accumulation | E7: =E6+Assumptions!$B$21*1 -> 47.5 | F7: =F6+Assumptions!$B$21*2 -> 48 | G7: =G6+Assumptions!$B$21*3 -> 48.5 | H7: =H6+Assumptions!$B$21*4 -> 49 | I7: =I6+Assumptions!$B$21*5 -> 49.5 | J7: =J6+Assumptions!$B$21*6 -> 50 | K7: =K6+Assumptions!$B$21*7 -> 50.5 | L7: =L6+Assumptions!$B$21*8 -> 51 | M7: =M6+Assumptions!$B$21*9 -> 51.5 | N7: =N6+Assumptions!$B$21*10 -> 52 | O7: =O6+Assumptions!$B$21*11 -> 52.5 | P7: =P6+Assumptions!$B$21*12 -> 53 | Q7: =Q6+Assumptions!$B$21*13 -> 53.5 | R7: =R6+Assumptions!$B$21*14 -> 54 | S7: =S6+Assumptions!$B$21*15 -> 54.5 | T7: =T6+Assumptions!$B$21*16 -> 55 | U7: =U6+Assumptions!$B$21*17 -> 55.5 | V7: =V6+Assumptions!$B$21*18 -> 56 | W7: =W6+Assumptions!$B$21*19 -> 56.5 | X7: =X6+Assumptions!$B$21*20 -> 57 | Y7: Verify Assumptions!
A9: Delta-CWP-SOC,t | B9: t C | C9: Soil organic carbon change | E9: =E5*(E7-E6) -> 1000 | F9: =F5*(F7-F6) -> 4000 | G9: =G5*(G7-G6) -> 6000 | H9: =H5*(H7-H6) -> 8000 | I9: =I5*(I7-I6) -> 10000 | J9: =J5*(J7-J6) -> 12000 | K9: =K5*(K7-K6) -> 14000 | L9: =L5*(L7-L6) -> 16000 | ... X9: =X5*(X7-X6) -> 40000
A16: Notes
A17: Scientific References: Study 1: Grinand et al. (2017). https://agritrop.cirad.fr/581670/1/Grinand2017-JAG.pdf Source: International Journal of Applied Earth Observation and Geoinformation 54: 1-14 Location: Southeast Madagascar (43,000 ha study area) Findings: Humid region cropland/savannah: 61.0 Mg C/ha (0-30 cm), 125.4 Mg C/ha (0-100 cm) Dry region cropland/savannah: 46.8 Mg C/ha (0-30 cm), 94.7 Mg C/ha (0-100 cm) Time Profile: Years 1-3: Minimal SOC increase (establishment phase) Years 4-10: Peak accumulation at ~0.5 t C/ha/year Years 10+: Gradual decline to equilibrium (~0.2-0.3 t C/ha/year)

Sheet Eq3_Delta_woody
A1: Eq3: Woody biomass carbon stock change (t C)
A4: Variable | B4: Value | C4: Description (with units) | D4: Notes | E4: Year 1 | F4: Year 2 | G4: Year 3 | H4: Year 4 | I4: Year 5 | J4: Year 6 | K4: Year 7 | L4: Year 8 | M4: Year 9 | N4: Year 10 | O4: Year 11 | P4: Year 12 | Q4: Year 13 | R4: Year 14 | S4: Year 15 | T4: Year 16 | U4: Year 17 | V4: Year 18 | W4: Year 19 | X4: Year 20
A5: A | B5: Ha | C5: Project area | D5: GIS measurement | E5: =Assumptions!E8 -> 2000 | F5: =Assumptions!F8 -> 4000 | G5: =Assumptions!G8 -> 4000 | H5: =Assumptions!H8 -> 4000 | I5: =Assumptions!I8 -> 4000 | J5: =Assumptions!J8 -> 4000 | K5: =Assumptions!K8 -> 4000 | L5: =Assumptions!L8 -> 4000 | ... X5: =Assumptions!X8 -> 4000
A6: CWP-woody,t=0 | B6: t C/ha | C6: Initial woody biomass carbon | D6: Pre-project baseline | E6: 0 | F6: 0 | G6: 0 | H6: 0 | I6: 0 | J6: 0 | K6: 0 | L6: 0 | M6: 0 | N6: 0 | O6: 0 | P6: 0 | Q6: 0 | R6: 0 | S6: 0 | T6: 0 | U6: 0 | V6: 0 | W6: 0 | X6: 0
A7: CWP-woody,t | B7: t C/ha | C7: Woody biomass carbon at year t | D7: From Eq4_CWP_woody | E7: =Eq4_CWP_woody!E9 -> 1.116 | F7: =Eq4_CWP_woody!F9 -> 5.208 | G7: =Eq4_CWP_woody!G9 -> 20.46 | H7: =Eq4_CWP_woody!H9 -> 39.06 | I7: =Eq4_CWP_woody!I9 -> 65.1 | J7: =Eq4_CWP_woody!J9 -> 86.8 | K7: =Eq4_CWP_woody!K9 -> 117.18 | L7: =Eq4_CWP_woody!L9 -> 151.9 | ... X7: =Eq4_CWP_woody!X9 -> 364.56
A9: Delta-CWP-woody,t | B9: t C | C9: Woody biomass carbon change | E9: =E5*(E7-E6) -> 2232 | F9: =F5*(F7-F6) -> 20832 | G9: =G5*(G7-G6) -> 81840 | H9: =H5*(H7-H6) -> 156240 | I9: =I5*(I7-I6) -> 260400 | J9: =J5*(J7-J6) -> 347200 | K9: =K5*(K7-K6) -> 468720 | L9: =L5*(L7-L6) -> 607600 | ... X9: =X5*(X7-X6) -> 1458240
A16: Notes
A17: Baseline assumes no trees in the project zone (along rivers). This might need correction.

Sheet Eq5_Delta_herb
A1: Eq5: Non-woody biomass carbon stock change (t C)
A4: Variable | B4: Value | C4: Description (with units) | D4: Notes | E4: Year 1 | F4: Year 2 | G4: Year 3 | H4: Year 4 | I4: Year 5 | J4: Year 6 | K4: Year 7 | L4: Year 8 | M4: Year 9 | N4: Year 10 | O4: Year 11 | P4: Year 12 | Q4: Year 13 | R4: Year 14 | S4: Year 15 | T4: Year 16 | U4: Year 17 | V4: Year 18 | W4: Year 19 | X4: Year 20
A5: A | B5: ha | C5: Project area | D5: GIS measurement | E5: =Assumptions!E8 -> 2000 | F5: =Assumptions!F8 -> 4000 | G5: =Assumptions!G8 -> 4000 | H5: =Assumptions!H8 -> 4000 | I5: =Assumptions!I8 -> 4000 | J5: =Assumptions!J8 -> 4000 | K5: =Assumptions!K8 -> 4000 | L5: =Assumptions!L8 -> 4000 | ... X5: =Assumptions!X8 -> 4000
A6: CWP-herb,t=0 | B6: t C/ha | C6: Initial non-woody biomass carbon | D6: Pre-project baseline | E6: 0 | F6: 0 | G6: 0 | H6: 0 | I6: 0 | J6: 0 | K6: 0 | L6: 0 | M6: 0 | N6: 0 | O6: 0 | P6: 0 | Q6: 0 | R6: 0 | S6: 0 | T6: 0 | U6: 0 | V6: 0 | W6: 0 | X6: 0
A7: CWP-herb,t | B7: t C/ha | C7: Non-woody biomass carbon at year t | D7: From Eq6_CWP_herb | E7: =Eq6_CWP_herb!E8 -> 1.41 | F7: =Eq6_CWP_herb!F8 -> 1.41 | G7: =Eq6_CWP_herb!G8 -> 0.94 | H7: =Eq6_CWP_herb!H8 -> 0.94 | I7: =Eq6_CWP_herb!I8 -> 0.705 | J7: =Eq6_CWP_herb!J8 -> 0.47 | K7: =Eq6_CWP_herb!K8 -> 0.47 | L7: =Eq6_CWP_herb!L8 -> 0.3525 | ... X7: =Eq6_CWP_herb!X8 -> 0.047
A9: Delta-CWP-herb,t | B9: t C | C9: Non-woody biomass carbon change | E9: =E5*(E7-E6) -> 2820 | F9: =F5*(F7-F6) -> 5640 | G9: =G5*(G7-G6) -> 3760 | H9: =H5*(H7-H6) -> 3760 | I9: =I5*(I7-I6) -> 2820 | J9: =J5*(J7-J6) -> 1880 | K9: =K5*(K7-K6) -> 1880 | L9: =L5*(L7-L6) -> 1410 | ... X9: =X5*(X7-X6) -> 188
A16: Notes
A17: Initial non-woody biomass carbon assumed zero: needs correction?

Sheet Eq7_Delta_DW
A1: Eq7: Dead wood carbon stock change (t C)
A4: Variable | B4: Value | C4: Description (with units) | D4: Notes | E4: Year 1 | F4: Year 2 | G4: Year 3 | H4: Year 4 | I4: Year 5 | J4: Year 6 | K4: Year 7 | L4: Year 8 | M4: Year 9 | N4: Year 10 | O4: Year 11 | P4: Year 12 | Q4: Year 13 | R4: Year 14 | S4: Year 15 | T4: Year 16 | U4: Year 17 | V4: Year 18 | W4: Year 19 | X4: Year 20
